version: "3.9"

volumes:
    postgis_db:
    pgadmin_data:


services:
  db:
    image: postgis/postgis
    volumes:
      - postgis_db:/var/lib/postgresql/data
    user: postgres
    environment:
      - POSTGRES_DB=postgres
      - POSTGRES_USER=postgres
      - POSTGRES_PASSWORD=jyhan123*
      - PGDATA=/var/lib/postgresql/data
    ports:
      - "5432:5432"
    healthcheck:
        test: ["CMD", "pg_isready"]
        timeout: 5s
        retries: 3
      
      
      
  pgadmin:
    image: dpage/pgadmin4
    environment:
      PGADMIN_DEFAULT_EMAIL: ${PGADMIN_DEFAULT_EMAIL:-gps@gmail.com}
      PGADMIN_DEFAULT_PASSWORD: ${PGADMIN_DEFAULT_PASSWORD:-jyhan123*}
    volumes:
       - pgadmin:/root/.pgadmin 
    ports:
      - "${PGADMIN_PORT:-5050}:80"
    restart: on-failure
    volumes:
      - pgadmin_data:/var/lib/pgadmin
    depends_on:
      db:
        condition: service_healthy
    
  web:
    build: .
    command: python manage.py runserver 0.0.0.0:8000
    volumes:
      - .:/code
    ports:
      - "8000:8000"
    depends_on:
      - db